2024-12-16 18:02:35,618 - uvicorn.error - INFO - [server.py:84] - Started server process [4436]
2024-12-16 18:02:35,619 - uvicorn.error - INFO - [on.py:45] - Waiting for application startup.
2024-12-16 18:02:35,619 - root - INFO - [main.py:33] - Starting up the application
2024-12-16 18:02:35,623 - root - INFO - [main.py:35] - Successfully connected to the database
2024-12-16 18:02:35,623 - uvicorn.error - INFO - [on.py:59] - Application startup complete.
2024-12-16 18:08:16,352 - uvicorn.error - INFO - [server.py:263] - Shutting down
2024-12-16 18:08:16,452 - uvicorn.error - INFO - [on.py:64] - Waiting for application shutdown.
2024-12-16 18:08:16,453 - uvicorn.error - INFO - [on.py:75] - Application shutdown complete.
2024-12-16 18:08:16,453 - uvicorn.error - INFO - [server.py:94] - Finished server process [4436]
2024-12-16 18:08:17,615 - uvicorn.error - INFO - [server.py:84] - Started server process [6831]
2024-12-16 18:08:17,615 - uvicorn.error - INFO - [on.py:45] - Waiting for application startup.
2024-12-16 18:08:17,616 - root - INFO - [main.py:33] - Starting up the application
2024-12-16 18:08:17,619 - root - INFO - [main.py:35] - Successfully connected to the database
2024-12-16 18:08:17,619 - uvicorn.error - INFO - [on.py:59] - Application startup complete.
2024-12-16 18:08:53,101 - uvicorn.error - INFO - [server.py:263] - Shutting down
2024-12-16 18:08:53,202 - uvicorn.error - INFO - [server.py:94] - Finished server process [6831]
2024-12-16 18:08:53,204 - uvicorn.error - ERROR - [on.py:132] - Traceback (most recent call last):
  File "/home/srihari/miniconda3/envs/appdev/lib/python3.13/site-packages/starlette/routing.py", line 700, in lifespan
    await receive()
  File "/home/srihari/miniconda3/envs/appdev/lib/python3.13/site-packages/uvicorn/lifespan/on.py", line 135, in receive
    return await self.receive_queue.get()
           ^^^^^^^^^^^^^^^^^^^^^^^^^^^^^^
  File "/home/srihari/miniconda3/envs/appdev/lib/python3.13/asyncio/queues.py", line 186, in get
    await getter
asyncio.exceptions.CancelledError

2024-12-16 18:09:04,283 - uvicorn.error - INFO - [server.py:84] - Started server process [7187]
2024-12-16 18:09:04,283 - uvicorn.error - INFO - [on.py:45] - Waiting for application startup.
2024-12-16 18:09:04,283 - root - INFO - [main.py:33] - Starting up the application
2024-12-16 18:09:04,286 - root - INFO - [main.py:35] - Successfully connected to the database
2024-12-16 18:09:04,286 - uvicorn.error - INFO - [on.py:59] - Application startup complete.
2024-12-16 18:11:11,824 - multipart.multipart - DEBUG - [multipart.py:586] - Calling on_field_start with no data
2024-12-16 18:11:11,824 - multipart.multipart - DEBUG - [multipart.py:583] - Calling on_field_name with data[0:8]
2024-12-16 18:11:11,824 - multipart.multipart - DEBUG - [multipart.py:583] - Calling on_field_data with data[9:12]
2024-12-16 18:11:11,824 - multipart.multipart - DEBUG - [multipart.py:586] - Calling on_field_end with no data
2024-12-16 18:11:11,824 - multipart.multipart - DEBUG - [multipart.py:586] - Calling on_field_start with no data
2024-12-16 18:11:11,824 - multipart.multipart - DEBUG - [multipart.py:583] - Calling on_field_name with data[13:21]
2024-12-16 18:11:11,824 - multipart.multipart - DEBUG - [multipart.py:583] - Calling on_field_data with data[22:28]
2024-12-16 18:11:11,824 - multipart.multipart - DEBUG - [multipart.py:586] - Calling on_field_end with no data
2024-12-16 18:11:11,824 - multipart.multipart - DEBUG - [multipart.py:586] - Calling on_end with no data
2024-12-16 18:11:12,062 - app.api.endpoints - INFO - [endpoints.py:85] - Successful login for user: sri
2024-12-16 18:13:15,572 - uvicorn.error - INFO - [server.py:263] - Shutting down
2024-12-16 18:13:15,673 - uvicorn.error - INFO - [on.py:64] - Waiting for application shutdown.
2024-12-16 18:13:15,673 - uvicorn.error - INFO - [on.py:75] - Application shutdown complete.
2024-12-16 18:13:15,673 - uvicorn.error - INFO - [server.py:94] - Finished server process [7187]
2024-12-16 18:13:16,837 - uvicorn.error - INFO - [server.py:84] - Started server process [8896]
2024-12-16 18:13:16,838 - uvicorn.error - INFO - [on.py:45] - Waiting for application startup.
2024-12-16 18:13:16,838 - root - INFO - [main.py:33] - Starting up the application
2024-12-16 18:13:16,842 - root - INFO - [main.py:35] - Successfully connected to the database
2024-12-16 18:13:16,842 - uvicorn.error - INFO - [on.py:59] - Application startup complete.
2024-12-16 18:14:40,156 - uvicorn.error - INFO - [server.py:263] - Shutting down
2024-12-16 18:14:40,258 - uvicorn.error - INFO - [on.py:64] - Waiting for application shutdown.
2024-12-16 18:14:40,258 - uvicorn.error - INFO - [on.py:75] - Application shutdown complete.
2024-12-16 18:14:40,258 - uvicorn.error - INFO - [server.py:94] - Finished server process [8896]
2024-12-16 18:14:41,329 - uvicorn.error - INFO - [server.py:84] - Started server process [9330]
2024-12-16 18:14:41,330 - uvicorn.error - INFO - [on.py:45] - Waiting for application startup.
2024-12-16 18:14:41,330 - root - INFO - [main.py:33] - Starting up the application
2024-12-16 18:14:41,335 - root - INFO - [main.py:35] - Successfully connected to the database
2024-12-16 18:14:41,335 - uvicorn.error - INFO - [on.py:59] - Application startup complete.
2024-12-16 18:15:58,009 - uvicorn.error - INFO - [server.py:263] - Shutting down
2024-12-16 18:15:58,110 - uvicorn.error - INFO - [on.py:64] - Waiting for application shutdown.
2024-12-16 18:15:58,111 - uvicorn.error - INFO - [on.py:75] - Application shutdown complete.
2024-12-16 18:15:58,111 - uvicorn.error - INFO - [server.py:94] - Finished server process [9330]
2024-12-16 18:15:59,237 - uvicorn.error - INFO - [server.py:84] - Started server process [9650]
2024-12-16 18:15:59,238 - uvicorn.error - INFO - [on.py:45] - Waiting for application startup.
2024-12-16 18:15:59,238 - root - INFO - [main.py:33] - Starting up the application
2024-12-16 18:15:59,242 - root - INFO - [main.py:35] - Successfully connected to the database
2024-12-16 18:15:59,243 - uvicorn.error - INFO - [on.py:59] - Application startup complete.
2024-12-16 18:16:47,399 - multipart.multipart - DEBUG - [multipart.py:586] - Calling on_field_start with no data
2024-12-16 18:16:47,399 - multipart.multipart - DEBUG - [multipart.py:583] - Calling on_field_name with data[0:8]
2024-12-16 18:16:47,399 - multipart.multipart - DEBUG - [multipart.py:583] - Calling on_field_data with data[9:12]
2024-12-16 18:16:47,399 - multipart.multipart - DEBUG - [multipart.py:586] - Calling on_field_end with no data
2024-12-16 18:16:47,399 - multipart.multipart - DEBUG - [multipart.py:586] - Calling on_field_start with no data
2024-12-16 18:16:47,399 - multipart.multipart - DEBUG - [multipart.py:583] - Calling on_field_name with data[13:21]
2024-12-16 18:16:47,399 - multipart.multipart - DEBUG - [multipart.py:583] - Calling on_field_data with data[22:28]
2024-12-16 18:16:47,399 - multipart.multipart - DEBUG - [multipart.py:586] - Calling on_field_end with no data
2024-12-16 18:16:47,399 - multipart.multipart - DEBUG - [multipart.py:586] - Calling on_end with no data
2024-12-16 18:16:47,639 - app.api.endpoints - INFO - [endpoints.py:85] - Successful login for user: sri
2024-12-16 18:18:40,899 - uvicorn.error - INFO - [server.py:263] - Shutting down
2024-12-16 18:18:40,999 - uvicorn.error - INFO - [on.py:64] - Waiting for application shutdown.
2024-12-16 18:18:41,000 - uvicorn.error - INFO - [on.py:75] - Application shutdown complete.
2024-12-16 18:18:41,000 - uvicorn.error - INFO - [server.py:94] - Finished server process [9650]
2024-12-16 18:18:42,147 - uvicorn.error - INFO - [server.py:84] - Started server process [10231]
2024-12-16 18:18:42,147 - uvicorn.error - INFO - [on.py:45] - Waiting for application startup.
2024-12-16 18:18:42,147 - root - INFO - [main.py:33] - Starting up the application
2024-12-16 18:18:42,151 - root - INFO - [main.py:35] - Successfully connected to the database
2024-12-16 18:18:42,151 - uvicorn.error - INFO - [on.py:59] - Application startup complete.
2024-12-16 18:19:48,731 - multipart.multipart - DEBUG - [multipart.py:586] - Calling on_field_start with no data
2024-12-16 18:19:48,731 - multipart.multipart - DEBUG - [multipart.py:583] - Calling on_field_name with data[0:8]
2024-12-16 18:19:48,731 - multipart.multipart - DEBUG - [multipart.py:583] - Calling on_field_data with data[9:12]
2024-12-16 18:19:48,731 - multipart.multipart - DEBUG - [multipart.py:586] - Calling on_field_end with no data
2024-12-16 18:19:48,732 - multipart.multipart - DEBUG - [multipart.py:586] - Calling on_field_start with no data
2024-12-16 18:19:48,732 - multipart.multipart - DEBUG - [multipart.py:583] - Calling on_field_name with data[13:21]
2024-12-16 18:19:48,732 - multipart.multipart - DEBUG - [multipart.py:583] - Calling on_field_data with data[22:28]
2024-12-16 18:19:48,732 - multipart.multipart - DEBUG - [multipart.py:586] - Calling on_field_end with no data
2024-12-16 18:19:48,732 - multipart.multipart - DEBUG - [multipart.py:586] - Calling on_end with no data
2024-12-16 18:19:48,963 - app.api.endpoints - INFO - [endpoints.py:85] - Successful login for user: sri
2024-12-16 18:20:14,228 - multipart.multipart - DEBUG - [multipart.py:586] - Calling on_field_start with no data
2024-12-16 18:20:14,228 - multipart.multipart - DEBUG - [multipart.py:583] - Calling on_field_name with data[0:8]
2024-12-16 18:20:14,228 - multipart.multipart - DEBUG - [multipart.py:583] - Calling on_field_data with data[9:12]
2024-12-16 18:20:14,228 - multipart.multipart - DEBUG - [multipart.py:586] - Calling on_field_end with no data
2024-12-16 18:20:14,229 - multipart.multipart - DEBUG - [multipart.py:586] - Calling on_field_start with no data
2024-12-16 18:20:14,229 - multipart.multipart - DEBUG - [multipart.py:583] - Calling on_field_name with data[13:21]
2024-12-16 18:20:14,229 - multipart.multipart - DEBUG - [multipart.py:583] - Calling on_field_data with data[22:28]
2024-12-16 18:20:14,229 - multipart.multipart - DEBUG - [multipart.py:586] - Calling on_field_end with no data
2024-12-16 18:20:14,229 - multipart.multipart - DEBUG - [multipart.py:586] - Calling on_end with no data
2024-12-16 18:20:14,457 - app.api.endpoints - INFO - [endpoints.py:85] - Successful login for user: sri
2024-12-16 18:21:08,085 - uvicorn.error - INFO - [server.py:263] - Shutting down
2024-12-16 18:21:08,185 - uvicorn.error - INFO - [on.py:64] - Waiting for application shutdown.
2024-12-16 18:21:08,186 - uvicorn.error - INFO - [on.py:75] - Application shutdown complete.
2024-12-16 18:21:08,186 - uvicorn.error - INFO - [server.py:94] - Finished server process [10231]
2024-12-16 18:21:09,204 - uvicorn.error - INFO - [server.py:84] - Started server process [10798]
2024-12-16 18:21:09,204 - uvicorn.error - INFO - [on.py:45] - Waiting for application startup.
2024-12-16 18:21:09,205 - root - INFO - [main.py:33] - Starting up the application
2024-12-16 18:21:09,209 - root - INFO - [main.py:35] - Successfully connected to the database
2024-12-16 18:21:09,210 - uvicorn.error - INFO - [on.py:59] - Application startup complete.
2024-12-16 18:21:22,442 - uvicorn.error - INFO - [server.py:263] - Shutting down
2024-12-16 18:21:22,542 - uvicorn.error - INFO - [on.py:64] - Waiting for application shutdown.
2024-12-16 18:21:22,543 - uvicorn.error - INFO - [on.py:75] - Application shutdown complete.
2024-12-16 18:21:22,543 - uvicorn.error - INFO - [server.py:94] - Finished server process [10798]
2024-12-16 18:21:23,664 - uvicorn.error - INFO - [server.py:84] - Started server process [10866]
2024-12-16 18:21:23,664 - uvicorn.error - INFO - [on.py:45] - Waiting for application startup.
2024-12-16 18:21:23,664 - root - INFO - [main.py:33] - Starting up the application
2024-12-16 18:21:23,668 - root - INFO - [main.py:35] - Successfully connected to the database
2024-12-16 18:21:23,668 - uvicorn.error - INFO - [on.py:59] - Application startup complete.
2024-12-16 18:21:33,791 - uvicorn.error - INFO - [server.py:263] - Shutting down
2024-12-16 18:21:33,892 - uvicorn.error - INFO - [on.py:64] - Waiting for application shutdown.
2024-12-16 18:21:33,893 - uvicorn.error - INFO - [on.py:75] - Application shutdown complete.
2024-12-16 18:21:33,893 - uvicorn.error - INFO - [server.py:94] - Finished server process [10866]
2024-12-16 18:21:35,030 - uvicorn.error - INFO - [server.py:84] - Started server process [10923]
2024-12-16 18:21:35,031 - uvicorn.error - INFO - [on.py:45] - Waiting for application startup.
2024-12-16 18:21:35,031 - root - INFO - [main.py:33] - Starting up the application
2024-12-16 18:21:35,035 - root - INFO - [main.py:35] - Successfully connected to the database
2024-12-16 18:21:35,035 - uvicorn.error - INFO - [on.py:59] - Application startup complete.
2024-12-16 18:22:11,897 - multipart.multipart - DEBUG - [multipart.py:586] - Calling on_field_start with no data
2024-12-16 18:22:11,897 - multipart.multipart - DEBUG - [multipart.py:583] - Calling on_field_name with data[0:8]
2024-12-16 18:22:11,898 - multipart.multipart - DEBUG - [multipart.py:583] - Calling on_field_data with data[9:12]
2024-12-16 18:22:11,898 - multipart.multipart - DEBUG - [multipart.py:586] - Calling on_field_end with no data
2024-12-16 18:22:11,898 - multipart.multipart - DEBUG - [multipart.py:586] - Calling on_field_start with no data
2024-12-16 18:22:11,898 - multipart.multipart - DEBUG - [multipart.py:583] - Calling on_field_name with data[13:21]
2024-12-16 18:22:11,898 - multipart.multipart - DEBUG - [multipart.py:583] - Calling on_field_data with data[22:28]
2024-12-16 18:22:11,898 - multipart.multipart - DEBUG - [multipart.py:586] - Calling on_field_end with no data
2024-12-16 18:22:11,898 - multipart.multipart - DEBUG - [multipart.py:586] - Calling on_end with no data
2024-12-16 18:22:12,286 - app.api.endpoints - INFO - [endpoints.py:85] - Successful login for user: sri
2024-12-16 18:22:36,140 - multipart.multipart - DEBUG - [multipart.py:586] - Calling on_field_start with no data
2024-12-16 18:22:36,140 - multipart.multipart - DEBUG - [multipart.py:583] - Calling on_field_name with data[0:8]
2024-12-16 18:22:36,140 - multipart.multipart - DEBUG - [multipart.py:583] - Calling on_field_data with data[9:12]
2024-12-16 18:22:36,140 - multipart.multipart - DEBUG - [multipart.py:586] - Calling on_field_end with no data
2024-12-16 18:22:36,140 - multipart.multipart - DEBUG - [multipart.py:586] - Calling on_field_start with no data
2024-12-16 18:22:36,140 - multipart.multipart - DEBUG - [multipart.py:583] - Calling on_field_name with data[13:21]
2024-12-16 18:22:36,140 - multipart.multipart - DEBUG - [multipart.py:583] - Calling on_field_data with data[22:28]
2024-12-16 18:22:36,140 - multipart.multipart - DEBUG - [multipart.py:586] - Calling on_field_end with no data
2024-12-16 18:22:36,140 - multipart.multipart - DEBUG - [multipart.py:586] - Calling on_end with no data
2024-12-16 18:22:36,383 - app.api.endpoints - INFO - [endpoints.py:85] - Successful login for user: sri
2024-12-16 18:23:35,908 - app.api.endpoints - INFO - [endpoints.py:282] - All users cleared. 1 users deleted.
2024-12-16 18:24:55,105 - uvicorn.error - INFO - [server.py:263] - Shutting down
2024-12-16 18:24:55,205 - uvicorn.error - INFO - [on.py:64] - Waiting for application shutdown.
2024-12-16 18:24:55,206 - uvicorn.error - INFO - [on.py:75] - Application shutdown complete.
2024-12-16 18:24:55,206 - uvicorn.error - INFO - [server.py:94] - Finished server process [10923]
2024-12-16 18:24:56,432 - uvicorn.error - INFO - [server.py:84] - Started server process [11667]
2024-12-16 18:24:56,432 - uvicorn.error - INFO - [on.py:45] - Waiting for application startup.
2024-12-16 18:24:56,433 - root - INFO - [main.py:33] - Starting up the application
2024-12-16 18:24:56,437 - root - INFO - [main.py:35] - Successfully connected to the database
2024-12-16 18:24:56,437 - uvicorn.error - INFO - [on.py:59] - Application startup complete.
2024-12-16 18:25:09,770 - uvicorn.error - INFO - [server.py:263] - Shutting down
2024-12-16 18:25:09,871 - uvicorn.error - INFO - [on.py:64] - Waiting for application shutdown.
2024-12-16 18:25:09,871 - uvicorn.error - INFO - [on.py:75] - Application shutdown complete.
2024-12-16 18:25:09,872 - uvicorn.error - INFO - [server.py:94] - Finished server process [11667]
2024-12-16 18:25:10,937 - uvicorn.error - INFO - [server.py:84] - Started server process [11782]
2024-12-16 18:25:10,937 - uvicorn.error - INFO - [on.py:45] - Waiting for application startup.
2024-12-16 18:25:10,938 - root - INFO - [main.py:33] - Starting up the application
2024-12-16 18:25:10,942 - root - INFO - [main.py:35] - Successfully connected to the database
2024-12-16 18:25:10,942 - uvicorn.error - INFO - [on.py:59] - Application startup complete.
2024-12-16 18:26:49,104 - app.api.endpoints - ERROR - [endpoints.py:314] - Error clearing users: 400: Confirmation not provided
Traceback (most recent call last):
  File "/home/srihari/Documents/Projects/App Dev/backend/app/api/endpoints.py", line 302, in clear_all_users
    raise HTTPException(status_code=400, detail="Confirmation not provided")
fastapi.exceptions.HTTPException: 400: Confirmation not provided
2024-12-16 18:28:38,245 - uvicorn.error - INFO - [server.py:263] - Shutting down
2024-12-16 18:28:38,345 - uvicorn.error - INFO - [on.py:64] - Waiting for application shutdown.
2024-12-16 18:28:38,346 - uvicorn.error - INFO - [on.py:75] - Application shutdown complete.
2024-12-16 18:28:38,346 - uvicorn.error - INFO - [server.py:94] - Finished server process [11782]
2024-12-16 18:30:38,969 - uvicorn.error - INFO - [server.py:84] - Started server process [13666]
2024-12-16 18:30:38,969 - uvicorn.error - INFO - [on.py:45] - Waiting for application startup.
2024-12-16 18:30:38,970 - root - INFO - [main.py:33] - Starting up the application
2024-12-16 18:30:38,974 - root - INFO - [main.py:35] - Successfully connected to the database
2024-12-16 18:30:38,974 - uvicorn.error - INFO - [on.py:59] - Application startup complete.
2024-12-16 18:31:53,862 - uvicorn.error - INFO - [server.py:263] - Shutting down
2024-12-16 18:31:53,963 - uvicorn.error - INFO - [on.py:64] - Waiting for application shutdown.
2024-12-16 18:31:53,964 - uvicorn.error - INFO - [on.py:75] - Application shutdown complete.
2024-12-16 18:31:53,964 - uvicorn.error - INFO - [server.py:94] - Finished server process [13666]
2024-12-16 18:53:29,021 - root - INFO - [main.py:33] - Starting up the application
2024-12-16 18:53:29,025 - root - INFO - [main.py:35] - Successfully connected to the database
2024-12-16 18:54:16,106 - passlib.handlers.bcrypt - DEBUG - [bcrypt.py:625] - detected 'bcrypt' backend, version '4.0.1'
2024-12-16 18:54:16,107 - passlib.handlers.bcrypt - DEBUG - [bcrypt.py:406] - 'bcrypt' backend lacks $2$ support, enabling workaround
2024-12-16 18:54:55,528 - multipart.multipart - DEBUG - [multipart.py:586] - Calling on_field_start with no data
2024-12-16 18:54:55,528 - multipart.multipart - DEBUG - [multipart.py:583] - Calling on_field_name with data[0:8]
2024-12-16 18:54:55,529 - multipart.multipart - DEBUG - [multipart.py:583] - Calling on_field_data with data[9:12]
2024-12-16 18:54:55,529 - multipart.multipart - DEBUG - [multipart.py:586] - Calling on_field_end with no data
2024-12-16 18:54:55,529 - multipart.multipart - DEBUG - [multipart.py:586] - Calling on_field_start with no data
2024-12-16 18:54:55,529 - multipart.multipart - DEBUG - [multipart.py:583] - Calling on_field_name with data[13:21]
2024-12-16 18:54:55,529 - multipart.multipart - DEBUG - [multipart.py:583] - Calling on_field_data with data[22:28]
2024-12-16 18:54:55,529 - multipart.multipart - DEBUG - [multipart.py:586] - Calling on_field_end with no data
2024-12-16 18:54:55,529 - multipart.multipart - DEBUG - [multipart.py:586] - Calling on_end with no data
2024-12-16 18:55:45,619 - multipart.multipart - DEBUG - [multipart.py:586] - Calling on_field_start with no data
2024-12-16 18:55:45,619 - multipart.multipart - DEBUG - [multipart.py:583] - Calling on_field_name with data[0:8]
2024-12-16 18:55:45,619 - multipart.multipart - DEBUG - [multipart.py:583] - Calling on_field_data with data[9:12]
2024-12-16 18:55:45,619 - multipart.multipart - DEBUG - [multipart.py:586] - Calling on_field_end with no data
2024-12-16 18:55:45,619 - multipart.multipart - DEBUG - [multipart.py:586] - Calling on_field_start with no data
2024-12-16 18:55:45,619 - multipart.multipart - DEBUG - [multipart.py:583] - Calling on_field_name with data[13:21]
2024-12-16 18:55:45,619 - multipart.multipart - DEBUG - [multipart.py:583] - Calling on_field_data with data[22:28]
2024-12-16 18:55:45,620 - multipart.multipart - DEBUG - [multipart.py:586] - Calling on_field_end with no data
2024-12-16 18:55:45,620 - multipart.multipart - DEBUG - [multipart.py:586] - Calling on_end with no data
2024-12-16 18:58:43,792 - root - INFO - [main.py:33] - Starting up the application
2024-12-16 18:58:43,795 - root - INFO - [main.py:35] - Successfully connected to the database
2024-12-16 18:58:55,794 - multipart.multipart - DEBUG - [multipart.py:586] - Calling on_field_start with no data
2024-12-16 18:58:55,794 - multipart.multipart - DEBUG - [multipart.py:583] - Calling on_field_name with data[0:8]
2024-12-16 18:58:55,794 - multipart.multipart - DEBUG - [multipart.py:583] - Calling on_field_data with data[9:12]
2024-12-16 18:58:55,795 - multipart.multipart - DEBUG - [multipart.py:586] - Calling on_field_end with no data
2024-12-16 18:58:55,795 - multipart.multipart - DEBUG - [multipart.py:586] - Calling on_field_start with no data
2024-12-16 18:58:55,795 - multipart.multipart - DEBUG - [multipart.py:583] - Calling on_field_name with data[13:21]
2024-12-16 18:58:55,795 - multipart.multipart - DEBUG - [multipart.py:583] - Calling on_field_data with data[22:28]
2024-12-16 18:58:55,795 - multipart.multipart - DEBUG - [multipart.py:586] - Calling on_field_end with no data
2024-12-16 18:58:55,795 - multipart.multipart - DEBUG - [multipart.py:586] - Calling on_end with no data
2024-12-16 18:58:55,799 - passlib.handlers.bcrypt - DEBUG - [bcrypt.py:625] - detected 'bcrypt' backend, version '4.0.1'
2024-12-16 18:58:55,799 - passlib.handlers.bcrypt - DEBUG - [bcrypt.py:406] - 'bcrypt' backend lacks $2$ support, enabling workaround
2024-12-16 19:22:42,391 - root - INFO - [main.py:33] - Starting up the application
2024-12-16 19:22:42,394 - root - INFO - [main.py:35] - Successfully connected to the database
2024-12-16 19:28:02,332 - multipart.multipart - DEBUG - [multipart.py:586] - Calling on_field_start with no data
2024-12-16 19:28:02,332 - multipart.multipart - DEBUG - [multipart.py:583] - Calling on_field_name with data[0:8]
2024-12-16 19:28:02,332 - multipart.multipart - DEBUG - [multipart.py:583] - Calling on_field_data with data[9:12]
2024-12-16 19:28:02,332 - multipart.multipart - DEBUG - [multipart.py:586] - Calling on_field_end with no data
2024-12-16 19:28:02,332 - multipart.multipart - DEBUG - [multipart.py:586] - Calling on_field_start with no data
2024-12-16 19:28:02,332 - multipart.multipart - DEBUG - [multipart.py:583] - Calling on_field_name with data[13:21]
2024-12-16 19:28:02,332 - multipart.multipart - DEBUG - [multipart.py:583] - Calling on_field_data with data[22:28]
2024-12-16 19:28:02,332 - multipart.multipart - DEBUG - [multipart.py:586] - Calling on_field_end with no data
2024-12-16 19:28:02,332 - multipart.multipart - DEBUG - [multipart.py:586] - Calling on_end with no data
2024-12-16 19:28:02,334 - passlib.handlers.bcrypt - DEBUG - [bcrypt.py:625] - detected 'bcrypt' backend, version '4.0.1'
2024-12-16 19:28:02,334 - passlib.handlers.bcrypt - DEBUG - [bcrypt.py:406] - 'bcrypt' backend lacks $2$ support, enabling workaround
2024-12-16 19:32:25,140 - root - INFO - [main.py:33] - Starting up the application
2024-12-16 19:32:25,144 - root - INFO - [main.py:35] - Successfully connected to the database
2024-12-16 19:38:38,471 - root - INFO - [main.py:33] - Starting up the application
2024-12-16 19:38:38,475 - root - INFO - [main.py:35] - Successfully connected to the database
2024-12-16 19:38:52,668 - root - INFO - [main.py:33] - Starting up the application
2024-12-16 19:38:52,672 - root - INFO - [main.py:35] - Successfully connected to the database
2024-12-16 19:47:15,245 - multipart.multipart - DEBUG - [multipart.py:586] - Calling on_field_start with no data
2024-12-16 19:47:15,246 - multipart.multipart - DEBUG - [multipart.py:583] - Calling on_field_name with data[0:8]
2024-12-16 19:47:15,246 - multipart.multipart - DEBUG - [multipart.py:583] - Calling on_field_data with data[9:12]
2024-12-16 19:47:15,246 - multipart.multipart - DEBUG - [multipart.py:586] - Calling on_field_end with no data
2024-12-16 19:47:15,246 - multipart.multipart - DEBUG - [multipart.py:586] - Calling on_field_start with no data
2024-12-16 19:47:15,246 - multipart.multipart - DEBUG - [multipart.py:583] - Calling on_field_name with data[13:21]
2024-12-16 19:47:15,246 - multipart.multipart - DEBUG - [multipart.py:583] - Calling on_field_data with data[22:28]
2024-12-16 19:47:15,246 - multipart.multipart - DEBUG - [multipart.py:586] - Calling on_field_end with no data
2024-12-16 19:47:15,246 - multipart.multipart - DEBUG - [multipart.py:586] - Calling on_end with no data
2024-12-16 19:47:15,249 - passlib.handlers.bcrypt - DEBUG - [bcrypt.py:625] - detected 'bcrypt' backend, version '4.0.1'
2024-12-16 19:47:15,250 - passlib.handlers.bcrypt - DEBUG - [bcrypt.py:406] - 'bcrypt' backend lacks $2$ support, enabling workaround
2024-12-16 19:49:43,753 - multipart.multipart - DEBUG - [multipart.py:586] - Calling on_field_start with no data
2024-12-16 19:49:43,753 - multipart.multipart - DEBUG - [multipart.py:583] - Calling on_field_name with data[0:8]
2024-12-16 19:49:43,753 - multipart.multipart - DEBUG - [multipart.py:583] - Calling on_field_data with data[9:12]
2024-12-16 19:49:43,753 - multipart.multipart - DEBUG - [multipart.py:586] - Calling on_field_end with no data
2024-12-16 19:49:43,753 - multipart.multipart - DEBUG - [multipart.py:586] - Calling on_field_start with no data
2024-12-16 19:49:43,753 - multipart.multipart - DEBUG - [multipart.py:583] - Calling on_field_name with data[13:21]
2024-12-16 19:49:43,754 - multipart.multipart - DEBUG - [multipart.py:583] - Calling on_field_data with data[22:28]
2024-12-16 19:49:43,754 - multipart.multipart - DEBUG - [multipart.py:586] - Calling on_field_end with no data
2024-12-16 19:49:43,754 - multipart.multipart - DEBUG - [multipart.py:586] - Calling on_end with no data
2024-12-16 20:24:24,861 - multipart.multipart - DEBUG - [multipart.py:586] - Calling on_field_start with no data
2024-12-16 20:24:24,861 - multipart.multipart - DEBUG - [multipart.py:583] - Calling on_field_name with data[0:8]
2024-12-16 20:24:24,861 - multipart.multipart - DEBUG - [multipart.py:583] - Calling on_field_data with data[9:12]
2024-12-16 20:24:24,861 - multipart.multipart - DEBUG - [multipart.py:586] - Calling on_field_end with no data
2024-12-16 20:24:24,861 - multipart.multipart - DEBUG - [multipart.py:586] - Calling on_field_start with no data
2024-12-16 20:24:24,861 - multipart.multipart - DEBUG - [multipart.py:583] - Calling on_field_name with data[13:21]
2024-12-16 20:24:24,861 - multipart.multipart - DEBUG - [multipart.py:583] - Calling on_field_data with data[22:28]
2024-12-16 20:24:24,861 - multipart.multipart - DEBUG - [multipart.py:586] - Calling on_field_end with no data
2024-12-16 20:24:24,861 - multipart.multipart - DEBUG - [multipart.py:586] - Calling on_end with no data
2024-12-16 20:24:56,028 - multipart.multipart - DEBUG - [multipart.py:586] - Calling on_field_start with no data
2024-12-16 20:24:56,028 - multipart.multipart - DEBUG - [multipart.py:583] - Calling on_field_name with data[0:8]
2024-12-16 20:24:56,028 - multipart.multipart - DEBUG - [multipart.py:583] - Calling on_field_data with data[9:12]
2024-12-16 20:24:56,028 - multipart.multipart - DEBUG - [multipart.py:586] - Calling on_field_end with no data
2024-12-16 20:24:56,028 - multipart.multipart - DEBUG - [multipart.py:586] - Calling on_field_start with no data
2024-12-16 20:24:56,028 - multipart.multipart - DEBUG - [multipart.py:583] - Calling on_field_name with data[13:21]
2024-12-16 20:24:56,028 - multipart.multipart - DEBUG - [multipart.py:583] - Calling on_field_data with data[22:28]
2024-12-16 20:24:56,029 - multipart.multipart - DEBUG - [multipart.py:586] - Calling on_field_end with no data
2024-12-16 20:24:56,029 - multipart.multipart - DEBUG - [multipart.py:586] - Calling on_end with no data
2024-12-16 20:27:01,304 - multipart.multipart - DEBUG - [multipart.py:586] - Calling on_field_start with no data
2024-12-16 20:27:01,304 - multipart.multipart - DEBUG - [multipart.py:583] - Calling on_field_name with data[0:8]
2024-12-16 20:27:01,304 - multipart.multipart - DEBUG - [multipart.py:583] - Calling on_field_data with data[9:13]
2024-12-16 20:27:01,304 - multipart.multipart - DEBUG - [multipart.py:586] - Calling on_field_end with no data
2024-12-16 20:27:01,304 - multipart.multipart - DEBUG - [multipart.py:586] - Calling on_field_start with no data
2024-12-16 20:27:01,304 - multipart.multipart - DEBUG - [multipart.py:583] - Calling on_field_name with data[14:22]
2024-12-16 20:27:01,305 - multipart.multipart - DEBUG - [multipart.py:583] - Calling on_field_data with data[23:29]
2024-12-16 20:27:01,305 - multipart.multipart - DEBUG - [multipart.py:586] - Calling on_field_end with no data
2024-12-16 20:27:01,308 - multipart.multipart - DEBUG - [multipart.py:586] - Calling on_end with no data
2024-12-16 20:28:36,254 - multipart.multipart - DEBUG - [multipart.py:586] - Calling on_field_start with no data
2024-12-16 20:28:36,254 - multipart.multipart - DEBUG - [multipart.py:583] - Calling on_field_name with data[0:8]
2024-12-16 20:28:36,254 - multipart.multipart - DEBUG - [multipart.py:583] - Calling on_field_data with data[9:12]
2024-12-16 20:28:36,254 - multipart.multipart - DEBUG - [multipart.py:586] - Calling on_field_end with no data
2024-12-16 20:28:36,254 - multipart.multipart - DEBUG - [multipart.py:586] - Calling on_field_start with no data
2024-12-16 20:28:36,254 - multipart.multipart - DEBUG - [multipart.py:583] - Calling on_field_name with data[13:21]
2024-12-16 20:28:36,254 - multipart.multipart - DEBUG - [multipart.py:583] - Calling on_field_data with data[22:28]
2024-12-16 20:28:36,254 - multipart.multipart - DEBUG - [multipart.py:586] - Calling on_field_end with no data
2024-12-16 20:28:36,254 - multipart.multipart - DEBUG - [multipart.py:586] - Calling on_end with no data
2024-12-16 20:39:45,960 - multipart.multipart - DEBUG - [multipart.py:586] - Calling on_field_start with no data
2024-12-16 20:39:45,960 - multipart.multipart - DEBUG - [multipart.py:583] - Calling on_field_name with data[0:8]
2024-12-16 20:39:45,960 - multipart.multipart - DEBUG - [multipart.py:583] - Calling on_field_data with data[9:12]
2024-12-16 20:39:45,960 - multipart.multipart - DEBUG - [multipart.py:586] - Calling on_field_end with no data
2024-12-16 20:39:45,960 - multipart.multipart - DEBUG - [multipart.py:586] - Calling on_field_start with no data
2024-12-16 20:39:45,960 - multipart.multipart - DEBUG - [multipart.py:583] - Calling on_field_name with data[13:21]
2024-12-16 20:39:45,960 - multipart.multipart - DEBUG - [multipart.py:583] - Calling on_field_data with data[22:28]
2024-12-16 20:39:45,960 - multipart.multipart - DEBUG - [multipart.py:586] - Calling on_field_end with no data
2024-12-16 20:39:45,960 - multipart.multipart - DEBUG - [multipart.py:586] - Calling on_end with no data
2024-12-16 20:42:18,324 - multipart.multipart - DEBUG - [multipart.py:586] - Calling on_field_start with no data
2024-12-16 20:42:18,325 - multipart.multipart - DEBUG - [multipart.py:583] - Calling on_field_name with data[0:8]
2024-12-16 20:42:18,325 - multipart.multipart - DEBUG - [multipart.py:583] - Calling on_field_data with data[9:12]
2024-12-16 20:42:18,325 - multipart.multipart - DEBUG - [multipart.py:586] - Calling on_field_end with no data
2024-12-16 20:42:18,325 - multipart.multipart - DEBUG - [multipart.py:586] - Calling on_field_start with no data
2024-12-16 20:42:18,325 - multipart.multipart - DEBUG - [multipart.py:583] - Calling on_field_name with data[13:21]
2024-12-16 20:42:18,325 - multipart.multipart - DEBUG - [multipart.py:583] - Calling on_field_data with data[22:28]
2024-12-16 20:42:18,325 - multipart.multipart - DEBUG - [multipart.py:586] - Calling on_field_end with no data
2024-12-16 20:42:18,325 - multipart.multipart - DEBUG - [multipart.py:586] - Calling on_end with no data
2024-12-16 20:43:44,159 - multipart.multipart - DEBUG - [multipart.py:586] - Calling on_field_start with no data
2024-12-16 20:43:44,160 - multipart.multipart - DEBUG - [multipart.py:583] - Calling on_field_name with data[0:8]
2024-12-16 20:43:44,160 - multipart.multipart - DEBUG - [multipart.py:583] - Calling on_field_data with data[9:13]
2024-12-16 20:43:44,160 - multipart.multipart - DEBUG - [multipart.py:586] - Calling on_field_end with no data
2024-12-16 20:43:44,160 - multipart.multipart - DEBUG - [multipart.py:586] - Calling on_field_start with no data
2024-12-16 20:43:44,161 - multipart.multipart - DEBUG - [multipart.py:583] - Calling on_field_name with data[14:22]
2024-12-16 20:43:44,161 - multipart.multipart - DEBUG - [multipart.py:583] - Calling on_field_data with data[23:29]
2024-12-16 20:43:44,161 - multipart.multipart - DEBUG - [multipart.py:586] - Calling on_field_end with no data
2024-12-16 20:43:44,161 - multipart.multipart - DEBUG - [multipart.py:586] - Calling on_end with no data
2024-12-16 20:47:59,814 - multipart.multipart - DEBUG - [multipart.py:586] - Calling on_field_start with no data
2024-12-16 20:47:59,814 - multipart.multipart - DEBUG - [multipart.py:583] - Calling on_field_name with data[0:8]
2024-12-16 20:47:59,814 - multipart.multipart - DEBUG - [multipart.py:583] - Calling on_field_data with data[9:12]
2024-12-16 20:47:59,814 - multipart.multipart - DEBUG - [multipart.py:586] - Calling on_field_end with no data
2024-12-16 20:47:59,814 - multipart.multipart - DEBUG - [multipart.py:586] - Calling on_field_start with no data
2024-12-16 20:47:59,814 - multipart.multipart - DEBUG - [multipart.py:583] - Calling on_field_name with data[13:21]
2024-12-16 20:47:59,814 - multipart.multipart - DEBUG - [multipart.py:583] - Calling on_field_data with data[22:28]
2024-12-16 20:47:59,814 - multipart.multipart - DEBUG - [multipart.py:586] - Calling on_field_end with no data
2024-12-16 20:47:59,814 - multipart.multipart - DEBUG - [multipart.py:586] - Calling on_end with no data
2024-12-16 21:06:42,718 - root - INFO - [main.py:33] - Starting up the application
2024-12-16 21:06:42,721 - root - INFO - [main.py:35] - Successfully connected to the database
2024-12-16 22:33:58,027 - root - INFO - [main.py:33] - Starting up the application
2024-12-16 22:33:58,032 - root - INFO - [main.py:35] - Successfully connected to the database
2024-12-16 22:49:23,854 - root - INFO - [main.py:33] - Starting up the application
2024-12-16 22:49:23,857 - root - INFO - [main.py:35] - Successfully connected to the database
2024-12-16 22:51:22,970 - root - INFO - [main.py:33] - Starting up the application
2024-12-16 22:51:23,006 - root - INFO - [main.py:35] - Successfully connected to the database
2024-12-16 22:52:40,168 - multipart.multipart - DEBUG - [multipart.py:586] - Calling on_field_start with no data
2024-12-16 22:52:40,168 - multipart.multipart - DEBUG - [multipart.py:583] - Calling on_field_name with data[0:8]
2024-12-16 22:52:40,168 - multipart.multipart - DEBUG - [multipart.py:583] - Calling on_field_data with data[9:12]
2024-12-16 22:52:40,168 - multipart.multipart - DEBUG - [multipart.py:586] - Calling on_field_end with no data
2024-12-16 22:52:40,168 - multipart.multipart - DEBUG - [multipart.py:586] - Calling on_field_start with no data
2024-12-16 22:52:40,168 - multipart.multipart - DEBUG - [multipart.py:583] - Calling on_field_name with data[13:21]
2024-12-16 22:52:40,168 - multipart.multipart - DEBUG - [multipart.py:583] - Calling on_field_data with data[22:28]
2024-12-16 22:52:40,168 - multipart.multipart - DEBUG - [multipart.py:586] - Calling on_field_end with no data
2024-12-16 22:52:40,168 - multipart.multipart - DEBUG - [multipart.py:586] - Calling on_end with no data
2024-12-16 22:52:40,172 - passlib.handlers.bcrypt - DEBUG - [bcrypt.py:625] - detected 'bcrypt' backend, version '4.0.1'
2024-12-16 22:52:40,172 - passlib.handlers.bcrypt - DEBUG - [bcrypt.py:406] - 'bcrypt' backend lacks $2$ support, enabling workaround
2024-12-16 22:53:13,438 - app.api.endpoints - ERROR - [endpoints.py:182] - Error creating expense: app.models.expense.Expense() got multiple values for keyword argument 'id'
Traceback (most recent call last):
  File "/home/srihari/Documents/Projects/App Dev/backend/app/api/endpoints.py", line 179, in create_expense
    return Expense(id=str(created_expense["_id"]),
          ^^^^^^^^^^^^^^^^^^^^^^^^^^^^^^^^^^^^^^^
TypeError: app.models.expense.Expense() got multiple values for keyword argument 'id'
2024-12-16 22:53:19,302 - app.api.endpoints - ERROR - [endpoints.py:182] - Error creating expense: app.models.expense.Expense() got multiple values for keyword argument 'id'
Traceback (most recent call last):
  File "/home/srihari/Documents/Projects/App Dev/backend/app/api/endpoints.py", line 179, in create_expense
    return Expense(id=str(created_expense["_id"]),
          ^^^^^^^^^^^^^^^^^^^^^^^^^^^^^^^^^^^^^^^
TypeError: app.models.expense.Expense() got multiple values for keyword argument 'id'
2024-12-16 22:54:41,207 - root - INFO - [main.py:33] - Starting up the application
2024-12-16 22:54:41,224 - root - INFO - [main.py:35] - Successfully connected to the database
2024-12-16 22:55:38,479 - app.api.endpoints - ERROR - [endpoints.py:198] - Error creating expense: 1 validation error for Expense
date
  Input should be a valid string [type=string_type, input_value=datetime.datetime(2024, 1... 16, 22, 55, 31, 159000), input_type=datetime]
    For further information visit https://errors.pydantic.dev/2.4/v/string_type
2024-12-16 22:55:48,243 - app.api.endpoints - ERROR - [endpoints.py:227] - Error fetching expenses: 1 validation error for Expense
date
  Input should be a valid string [type=string_type, input_value=datetime.datetime(2024, 1... 16, 22, 55, 31, 159000), input_type=datetime]
    For further information visit https://errors.pydantic.dev/2.4/v/string_type
Traceback (most recent call last):
  File "/home/srihari/Documents/Projects/App Dev/backend/app/api/endpoints.py", line 216, in get_expenses
    Expense(
  File "/home/srihari/miniconda3/envs/appdev_py312/lib/python3.12/site-packages/pydantic/main.py", line 164, in __init__
    __pydantic_self__.__pydantic_validator__.validate_python(data, self_instance=__pydantic_self__)
pydantic_core._pydantic_core.ValidationError: 1 validation error for Expense
date
  Input should be a valid string [type=string_type, input_value=datetime.datetime(2024, 1... 16, 22, 55, 31, 159000), input_type=datetime]
    For further information visit https://errors.pydantic.dev/2.4/v/string_type
2024-12-16 22:55:52,755 - app.api.endpoints - ERROR - [endpoints.py:227] - Error fetching expenses: 1 validation error for Expense
date
  Input should be a valid string [type=string_type, input_value=datetime.datetime(2024, 1... 16, 22, 55, 31, 159000), input_type=datetime]
    For further information visit https://errors.pydantic.dev/2.4/v/string_type
Traceback (most recent call last):
  File "/home/srihari/Documents/Projects/App Dev/backend/app/api/endpoints.py", line 216, in get_expenses
    Expense(
  File "/home/srihari/miniconda3/envs/appdev_py312/lib/python3.12/site-packages/pydantic/main.py", line 164, in __init__
    __pydantic_self__.__pydantic_validator__.validate_python(data, self_instance=__pydantic_self__)
pydantic_core._pydantic_core.ValidationError: 1 validation error for Expense
date
  Input should be a valid string [type=string_type, input_value=datetime.datetime(2024, 1... 16, 22, 55, 31, 159000), input_type=datetime]
    For further information visit https://errors.pydantic.dev/2.4/v/string_type
2024-12-16 22:55:53,345 - app.api.endpoints - ERROR - [endpoints.py:227] - Error fetching expenses: 1 validation error for Expense
date
  Input should be a valid string [type=string_type, input_value=datetime.datetime(2024, 1... 16, 22, 55, 31, 159000), input_type=datetime]
    For further information visit https://errors.pydantic.dev/2.4/v/string_type
Traceback (most recent call last):
  File "/home/srihari/Documents/Projects/App Dev/backend/app/api/endpoints.py", line 216, in get_expenses
    Expense(
  File "/home/srihari/miniconda3/envs/appdev_py312/lib/python3.12/site-packages/pydantic/main.py", line 164, in __init__
    __pydantic_self__.__pydantic_validator__.validate_python(data, self_instance=__pydantic_self__)
pydantic_core._pydantic_core.ValidationError: 1 validation error for Expense
date
  Input should be a valid string [type=string_type, input_value=datetime.datetime(2024, 1... 16, 22, 55, 31, 159000), input_type=datetime]
    For further information visit https://errors.pydantic.dev/2.4/v/string_type
2024-12-16 22:55:53,724 - app.api.endpoints - ERROR - [endpoints.py:227] - Error fetching expenses: 1 validation error for Expense
date
  Input should be a valid string [type=string_type, input_value=datetime.datetime(2024, 1... 16, 22, 55, 31, 159000), input_type=datetime]
    For further information visit https://errors.pydantic.dev/2.4/v/string_type
Traceback (most recent call last):
  File "/home/srihari/Documents/Projects/App Dev/backend/app/api/endpoints.py", line 216, in get_expenses
    Expense(
  File "/home/srihari/miniconda3/envs/appdev_py312/lib/python3.12/site-packages/pydantic/main.py", line 164, in __init__
    __pydantic_self__.__pydantic_validator__.validate_python(data, self_instance=__pydantic_self__)
pydantic_core._pydantic_core.ValidationError: 1 validation error for Expense
date
  Input should be a valid string [type=string_type, input_value=datetime.datetime(2024, 1... 16, 22, 55, 31, 159000), input_type=datetime]
    For further information visit https://errors.pydantic.dev/2.4/v/string_type
2024-12-16 22:56:07,921 - multipart.multipart - DEBUG - [multipart.py:586] - Calling on_field_start with no data
2024-12-16 22:56:07,922 - multipart.multipart - DEBUG - [multipart.py:583] - Calling on_field_name with data[0:8]
2024-12-16 22:56:07,922 - multipart.multipart - DEBUG - [multipart.py:583] - Calling on_field_data with data[9:12]
2024-12-16 22:56:07,922 - multipart.multipart - DEBUG - [multipart.py:586] - Calling on_field_end with no data
2024-12-16 22:56:07,922 - multipart.multipart - DEBUG - [multipart.py:586] - Calling on_field_start with no data
2024-12-16 22:56:07,922 - multipart.multipart - DEBUG - [multipart.py:583] - Calling on_field_name with data[13:21]
2024-12-16 22:56:07,922 - multipart.multipart - DEBUG - [multipart.py:583] - Calling on_field_data with data[22:28]
2024-12-16 22:56:07,922 - multipart.multipart - DEBUG - [multipart.py:586] - Calling on_field_end with no data
2024-12-16 22:56:07,922 - multipart.multipart - DEBUG - [multipart.py:586] - Calling on_end with no data
2024-12-16 22:56:07,924 - passlib.handlers.bcrypt - DEBUG - [bcrypt.py:625] - detected 'bcrypt' backend, version '4.0.1'
2024-12-16 22:56:07,924 - passlib.handlers.bcrypt - DEBUG - [bcrypt.py:406] - 'bcrypt' backend lacks $2$ support, enabling workaround
2024-12-16 22:56:08,382 - app.api.endpoints - ERROR - [endpoints.py:227] - Error fetching expenses: 1 validation error for Expense
date
  Input should be a valid string [type=string_type, input_value=datetime.datetime(2024, 1... 16, 22, 55, 31, 159000), input_type=datetime]
    For further information visit https://errors.pydantic.dev/2.4/v/string_type
Traceback (most recent call last):
  File "/home/srihari/Documents/Projects/App Dev/backend/app/api/endpoints.py", line 216, in get_expenses
    Expense(
  File "/home/srihari/miniconda3/envs/appdev_py312/lib/python3.12/site-packages/pydantic/main.py", line 164, in __init__
    __pydantic_self__.__pydantic_validator__.validate_python(data, self_instance=__pydantic_self__)
pydantic_core._pydantic_core.ValidationError: 1 validation error for Expense
date
  Input should be a valid string [type=string_type, input_value=datetime.datetime(2024, 1... 16, 22, 55, 31, 159000), input_type=datetime]
    For further information visit https://errors.pydantic.dev/2.4/v/string_type
2024-12-16 22:56:40,382 - app.api.endpoints - ERROR - [endpoints.py:227] - Error fetching expenses: 1 validation error for Expense
date
  Input should be a valid string [type=string_type, input_value=datetime.datetime(2024, 1... 16, 22, 55, 31, 159000), input_type=datetime]
    For further information visit https://errors.pydantic.dev/2.4/v/string_type
Traceback (most recent call last):
  File "/home/srihari/Documents/Projects/App Dev/backend/app/api/endpoints.py", line 216, in get_expenses
    Expense(
  File "/home/srihari/miniconda3/envs/appdev_py312/lib/python3.12/site-packages/pydantic/main.py", line 164, in __init__
    __pydantic_self__.__pydantic_validator__.validate_python(data, self_instance=__pydantic_self__)
pydantic_core._pydantic_core.ValidationError: 1 validation error for Expense
date
  Input should be a valid string [type=string_type, input_value=datetime.datetime(2024, 1... 16, 22, 55, 31, 159000), input_type=datetime]
    For further information visit https://errors.pydantic.dev/2.4/v/string_type
2024-12-16 22:56:44,562 - app.api.endpoints - ERROR - [endpoints.py:227] - Error fetching expenses: 1 validation error for Expense
date
  Input should be a valid string [type=string_type, input_value=datetime.datetime(2024, 1... 16, 22, 55, 31, 159000), input_type=datetime]
    For further information visit https://errors.pydantic.dev/2.4/v/string_type
Traceback (most recent call last):
  File "/home/srihari/Documents/Projects/App Dev/backend/app/api/endpoints.py", line 216, in get_expenses
    Expense(
  File "/home/srihari/miniconda3/envs/appdev_py312/lib/python3.12/site-packages/pydantic/main.py", line 164, in __init__
    __pydantic_self__.__pydantic_validator__.validate_python(data, self_instance=__pydantic_self__)
pydantic_core._pydantic_core.ValidationError: 1 validation error for Expense
date
  Input should be a valid string [type=string_type, input_value=datetime.datetime(2024, 1... 16, 22, 55, 31, 159000), input_type=datetime]
    For further information visit https://errors.pydantic.dev/2.4/v/string_type
2024-12-16 22:56:52,182 - app.api.endpoints - ERROR - [endpoints.py:227] - Error fetching expenses: 1 validation error for Expense
date
  Input should be a valid string [type=string_type, input_value=datetime.datetime(2024, 1... 16, 22, 55, 31, 159000), input_type=datetime]
    For further information visit https://errors.pydantic.dev/2.4/v/string_type
Traceback (most recent call last):
  File "/home/srihari/Documents/Projects/App Dev/backend/app/api/endpoints.py", line 216, in get_expenses
    Expense(
  File "/home/srihari/miniconda3/envs/appdev_py312/lib/python3.12/site-packages/pydantic/main.py", line 164, in __init__
    __pydantic_self__.__pydantic_validator__.validate_python(data, self_instance=__pydantic_self__)
pydantic_core._pydantic_core.ValidationError: 1 validation error for Expense
date
  Input should be a valid string [type=string_type, input_value=datetime.datetime(2024, 1... 16, 22, 55, 31, 159000), input_type=datetime]
    For further information visit https://errors.pydantic.dev/2.4/v/string_type
2024-12-16 22:56:53,994 - app.api.endpoints - ERROR - [endpoints.py:227] - Error fetching expenses: 1 validation error for Expense
date
  Input should be a valid string [type=string_type, input_value=datetime.datetime(2024, 1... 16, 22, 55, 31, 159000), input_type=datetime]
    For further information visit https://errors.pydantic.dev/2.4/v/string_type
Traceback (most recent call last):
  File "/home/srihari/Documents/Projects/App Dev/backend/app/api/endpoints.py", line 216, in get_expenses
    Expense(
  File "/home/srihari/miniconda3/envs/appdev_py312/lib/python3.12/site-packages/pydantic/main.py", line 164, in __init__
    __pydantic_self__.__pydantic_validator__.validate_python(data, self_instance=__pydantic_self__)
pydantic_core._pydantic_core.ValidationError: 1 validation error for Expense
date
  Input should be a valid string [type=string_type, input_value=datetime.datetime(2024, 1... 16, 22, 55, 31, 159000), input_type=datetime]
    For further information visit https://errors.pydantic.dev/2.4/v/string_type
2024-12-16 22:56:55,112 - app.api.endpoints - ERROR - [endpoints.py:227] - Error fetching expenses: 1 validation error for Expense
date
  Input should be a valid string [type=string_type, input_value=datetime.datetime(2024, 1... 16, 22, 55, 31, 159000), input_type=datetime]
    For further information visit https://errors.pydantic.dev/2.4/v/string_type
Traceback (most recent call last):
  File "/home/srihari/Documents/Projects/App Dev/backend/app/api/endpoints.py", line 216, in get_expenses
    Expense(
  File "/home/srihari/miniconda3/envs/appdev_py312/lib/python3.12/site-packages/pydantic/main.py", line 164, in __init__
    __pydantic_self__.__pydantic_validator__.validate_python(data, self_instance=__pydantic_self__)
pydantic_core._pydantic_core.ValidationError: 1 validation error for Expense
date
  Input should be a valid string [type=string_type, input_value=datetime.datetime(2024, 1... 16, 22, 55, 31, 159000), input_type=datetime]
    For further information visit https://errors.pydantic.dev/2.4/v/string_type
2024-12-16 22:56:56,116 - app.api.endpoints - ERROR - [endpoints.py:227] - Error fetching expenses: 1 validation error for Expense
date
  Input should be a valid string [type=string_type, input_value=datetime.datetime(2024, 1... 16, 22, 55, 31, 159000), input_type=datetime]
    For further information visit https://errors.pydantic.dev/2.4/v/string_type
Traceback (most recent call last):
  File "/home/srihari/Documents/Projects/App Dev/backend/app/api/endpoints.py", line 216, in get_expenses
    Expense(
  File "/home/srihari/miniconda3/envs/appdev_py312/lib/python3.12/site-packages/pydantic/main.py", line 164, in __init__
    __pydantic_self__.__pydantic_validator__.validate_python(data, self_instance=__pydantic_self__)
pydantic_core._pydantic_core.ValidationError: 1 validation error for Expense
date
  Input should be a valid string [type=string_type, input_value=datetime.datetime(2024, 1... 16, 22, 55, 31, 159000), input_type=datetime]
    For further information visit https://errors.pydantic.dev/2.4/v/string_type
2024-12-16 22:56:59,114 - root - INFO - [main.py:33] - Starting up the application
2024-12-16 22:56:59,120 - root - INFO - [main.py:35] - Successfully connected to the database
2024-12-16 22:57:43,846 - app.api.endpoints - ERROR - [endpoints.py:204] - Error creating expense: fromisoformat: argument must be str
2024-12-16 22:57:55,359 - root - INFO - [main.py:33] - Starting up the application
2024-12-16 22:57:55,368 - root - INFO - [main.py:35] - Successfully connected to the database
