2024-12-16 18:02:35,618 - INFO - Started server process [4436]
2024-12-16 18:02:35,619 - INFO - Waiting for application startup.
2024-12-16 18:02:35,619 - INFO - Starting up the application
2024-12-16 18:02:35,623 - INFO - Successfully connected to the database
2024-12-16 18:02:35,623 - INFO - Application startup complete.
2024-12-16 18:08:16,352 - INFO - Shutting down
2024-12-16 18:08:16,452 - INFO - Waiting for application shutdown.
2024-12-16 18:08:16,453 - INFO - Application shutdown complete.
2024-12-16 18:08:16,453 - INFO - Finished server process [4436]
2024-12-16 18:08:17,615 - INFO - Started server process [6831]
2024-12-16 18:08:17,615 - INFO - Waiting for application startup.
2024-12-16 18:08:17,616 - INFO - Starting up the application
2024-12-16 18:08:17,619 - INFO - Successfully connected to the database
2024-12-16 18:08:17,619 - INFO - Application startup complete.
2024-12-16 18:08:53,101 - INFO - Shutting down
2024-12-16 18:08:53,202 - INFO - Finished server process [6831]
2024-12-16 18:08:53,204 - ERROR - Traceback (most recent call last):
  File "/home/srihari/miniconda3/envs/appdev/lib/python3.13/site-packages/starlette/routing.py", line 700, in lifespan
    await receive()
  File "/home/srihari/miniconda3/envs/appdev/lib/python3.13/site-packages/uvicorn/lifespan/on.py", line 135, in receive
    return await self.receive_queue.get()
           ^^^^^^^^^^^^^^^^^^^^^^^^^^^^^^
  File "/home/srihari/miniconda3/envs/appdev/lib/python3.13/asyncio/queues.py", line 186, in get
    await getter
asyncio.exceptions.CancelledError

2024-12-16 18:09:04,283 - INFO - Started server process [7187]
2024-12-16 18:09:04,283 - INFO - Waiting for application startup.
2024-12-16 18:09:04,283 - INFO - Starting up the application
2024-12-16 18:09:04,286 - INFO - Successfully connected to the database
2024-12-16 18:09:04,286 - INFO - Application startup complete.
2024-12-16 18:11:12,062 - INFO - Successful login for user: sri
2024-12-16 18:13:15,572 - INFO - Shutting down
2024-12-16 18:13:15,673 - INFO - Waiting for application shutdown.
2024-12-16 18:13:15,673 - INFO - Application shutdown complete.
2024-12-16 18:13:15,673 - INFO - Finished server process [7187]
2024-12-16 18:13:16,837 - INFO - Started server process [8896]
2024-12-16 18:13:16,838 - INFO - Waiting for application startup.
2024-12-16 18:13:16,838 - INFO - Starting up the application
2024-12-16 18:13:16,842 - INFO - Successfully connected to the database
2024-12-16 18:13:16,842 - INFO - Application startup complete.
2024-12-16 18:14:40,156 - INFO - Shutting down
2024-12-16 18:14:40,258 - INFO - Waiting for application shutdown.
2024-12-16 18:14:40,258 - INFO - Application shutdown complete.
2024-12-16 18:14:40,258 - INFO - Finished server process [8896]
2024-12-16 18:14:41,329 - INFO - Started server process [9330]
2024-12-16 18:14:41,330 - INFO - Waiting for application startup.
2024-12-16 18:14:41,330 - INFO - Starting up the application
2024-12-16 18:14:41,335 - INFO - Successfully connected to the database
2024-12-16 18:14:41,335 - INFO - Application startup complete.
2024-12-16 18:15:58,009 - INFO - Shutting down
2024-12-16 18:15:58,110 - INFO - Waiting for application shutdown.
2024-12-16 18:15:58,111 - INFO - Application shutdown complete.
2024-12-16 18:15:58,111 - INFO - Finished server process [9330]
2024-12-16 18:15:59,237 - INFO - Started server process [9650]
2024-12-16 18:15:59,238 - INFO - Waiting for application startup.
2024-12-16 18:15:59,238 - INFO - Starting up the application
2024-12-16 18:15:59,242 - INFO - Successfully connected to the database
2024-12-16 18:15:59,243 - INFO - Application startup complete.
2024-12-16 18:16:47,639 - INFO - Successful login for user: sri
2024-12-16 18:18:40,899 - INFO - Shutting down
2024-12-16 18:18:40,999 - INFO - Waiting for application shutdown.
2024-12-16 18:18:41,000 - INFO - Application shutdown complete.
2024-12-16 18:18:41,000 - INFO - Finished server process [9650]
2024-12-16 18:18:42,147 - INFO - Started server process [10231]
2024-12-16 18:18:42,147 - INFO - Waiting for application startup.
2024-12-16 18:18:42,147 - INFO - Starting up the application
2024-12-16 18:18:42,151 - INFO - Successfully connected to the database
2024-12-16 18:18:42,151 - INFO - Application startup complete.
2024-12-16 18:19:48,963 - INFO - Successful login for user: sri
2024-12-16 18:20:14,457 - INFO - Successful login for user: sri
2024-12-16 18:21:08,085 - INFO - Shutting down
2024-12-16 18:21:08,185 - INFO - Waiting for application shutdown.
2024-12-16 18:21:08,186 - INFO - Application shutdown complete.
2024-12-16 18:21:08,186 - INFO - Finished server process [10231]
2024-12-16 18:21:09,204 - INFO - Started server process [10798]
2024-12-16 18:21:09,204 - INFO - Waiting for application startup.
2024-12-16 18:21:09,205 - INFO - Starting up the application
2024-12-16 18:21:09,209 - INFO - Successfully connected to the database
2024-12-16 18:21:09,210 - INFO - Application startup complete.
2024-12-16 18:21:22,442 - INFO - Shutting down
2024-12-16 18:21:22,542 - INFO - Waiting for application shutdown.
2024-12-16 18:21:22,543 - INFO - Application shutdown complete.
2024-12-16 18:21:22,543 - INFO - Finished server process [10798]
2024-12-16 18:21:23,664 - INFO - Started server process [10866]
2024-12-16 18:21:23,664 - INFO - Waiting for application startup.
2024-12-16 18:21:23,664 - INFO - Starting up the application
2024-12-16 18:21:23,668 - INFO - Successfully connected to the database
2024-12-16 18:21:23,668 - INFO - Application startup complete.
2024-12-16 18:21:33,791 - INFO - Shutting down
2024-12-16 18:21:33,892 - INFO - Waiting for application shutdown.
2024-12-16 18:21:33,893 - INFO - Application shutdown complete.
2024-12-16 18:21:33,893 - INFO - Finished server process [10866]
2024-12-16 18:21:35,030 - INFO - Started server process [10923]
2024-12-16 18:21:35,031 - INFO - Waiting for application startup.
2024-12-16 18:21:35,031 - INFO - Starting up the application
2024-12-16 18:21:35,035 - INFO - Successfully connected to the database
2024-12-16 18:21:35,035 - INFO - Application startup complete.
2024-12-16 18:22:12,286 - INFO - Successful login for user: sri
2024-12-16 18:22:36,383 - INFO - Successful login for user: sri
2024-12-16 18:23:35,908 - INFO - All users cleared. 1 users deleted.
2024-12-16 18:24:55,105 - INFO - Shutting down
2024-12-16 18:24:55,205 - INFO - Waiting for application shutdown.
2024-12-16 18:24:55,206 - INFO - Application shutdown complete.
2024-12-16 18:24:55,206 - INFO - Finished server process [10923]
2024-12-16 18:24:56,432 - INFO - Started server process [11667]
2024-12-16 18:24:56,432 - INFO - Waiting for application startup.
2024-12-16 18:24:56,433 - INFO - Starting up the application
2024-12-16 18:24:56,437 - INFO - Successfully connected to the database
2024-12-16 18:24:56,437 - INFO - Application startup complete.
2024-12-16 18:25:09,770 - INFO - Shutting down
2024-12-16 18:25:09,871 - INFO - Waiting for application shutdown.
2024-12-16 18:25:09,871 - INFO - Application shutdown complete.
2024-12-16 18:25:09,872 - INFO - Finished server process [11667]
2024-12-16 18:25:10,937 - INFO - Started server process [11782]
2024-12-16 18:25:10,937 - INFO - Waiting for application startup.
2024-12-16 18:25:10,938 - INFO - Starting up the application
2024-12-16 18:25:10,942 - INFO - Successfully connected to the database
2024-12-16 18:25:10,942 - INFO - Application startup complete.
2024-12-16 18:26:49,104 - ERROR - Error clearing users: 400: Confirmation not provided
Traceback (most recent call last):
  File "/home/srihari/Documents/Projects/App Dev/backend/app/api/endpoints.py", line 302, in clear_all_users
    raise HTTPException(status_code=400, detail="Confirmation not provided")
fastapi.exceptions.HTTPException: 400: Confirmation not provided
2024-12-16 18:28:38,245 - INFO - Shutting down
2024-12-16 18:28:38,345 - INFO - Waiting for application shutdown.
2024-12-16 18:28:38,346 - INFO - Application shutdown complete.
2024-12-16 18:28:38,346 - INFO - Finished server process [11782]
2024-12-16 18:30:38,969 - INFO - Started server process [13666]
2024-12-16 18:30:38,969 - INFO - Waiting for application startup.
2024-12-16 18:30:38,970 - INFO - Starting up the application
2024-12-16 18:30:38,974 - INFO - Successfully connected to the database
2024-12-16 18:30:38,974 - INFO - Application startup complete.
2024-12-16 18:31:53,862 - INFO - Shutting down
2024-12-16 18:31:53,963 - INFO - Waiting for application shutdown.
2024-12-16 18:31:53,964 - INFO - Application shutdown complete.
2024-12-16 18:31:53,964 - INFO - Finished server process [13666]
2024-12-16 18:53:29,021 - INFO - Starting up the application
2024-12-16 18:53:29,025 - INFO - Successfully connected to the database
2024-12-16 18:58:43,792 - INFO - Starting up the application
2024-12-16 18:58:43,795 - INFO - Successfully connected to the database
2024-12-16 19:22:42,391 - INFO - Starting up the application
2024-12-16 19:22:42,394 - INFO - Successfully connected to the database
2024-12-16 19:32:25,140 - INFO - Starting up the application
2024-12-16 19:32:25,144 - INFO - Successfully connected to the database
2024-12-16 19:38:38,471 - INFO - Starting up the application
2024-12-16 19:38:38,475 - INFO - Successfully connected to the database
2024-12-16 19:38:52,668 - INFO - Starting up the application
2024-12-16 19:38:52,672 - INFO - Successfully connected to the database
2024-12-16 21:06:42,718 - INFO - Starting up the application
2024-12-16 21:06:42,721 - INFO - Successfully connected to the database
2024-12-16 22:33:58,027 - INFO - Starting up the application
2024-12-16 22:33:58,032 - INFO - Successfully connected to the database
2024-12-16 22:49:23,854 - INFO - Starting up the application
2024-12-16 22:49:23,857 - INFO - Successfully connected to the database
2024-12-16 22:51:22,970 - INFO - Starting up the application
2024-12-16 22:51:23,006 - INFO - Successfully connected to the database
2024-12-16 22:53:13,438 - ERROR - Error creating expense: app.models.expense.Expense() got multiple values for keyword argument 'id'
Traceback (most recent call last):
  File "/home/srihari/Documents/Projects/App Dev/backend/app/api/endpoints.py", line 179, in create_expense
    return Expense(id=str(created_expense["_id"]),
          ^^^^^^^^^^^^^^^^^^^^^^^^^^^^^^^^^^^^^^^
TypeError: app.models.expense.Expense() got multiple values for keyword argument 'id'
2024-12-16 22:53:19,302 - ERROR - Error creating expense: app.models.expense.Expense() got multiple values for keyword argument 'id'
Traceback (most recent call last):
  File "/home/srihari/Documents/Projects/App Dev/backend/app/api/endpoints.py", line 179, in create_expense
    return Expense(id=str(created_expense["_id"]),
          ^^^^^^^^^^^^^^^^^^^^^^^^^^^^^^^^^^^^^^^
TypeError: app.models.expense.Expense() got multiple values for keyword argument 'id'
2024-12-16 22:54:41,207 - INFO - Starting up the application
2024-12-16 22:54:41,224 - INFO - Successfully connected to the database
2024-12-16 22:55:38,479 - ERROR - Error creating expense: 1 validation error for Expense
date
  Input should be a valid string [type=string_type, input_value=datetime.datetime(2024, 1... 16, 22, 55, 31, 159000), input_type=datetime]
    For further information visit https://errors.pydantic.dev/2.4/v/string_type
2024-12-16 22:55:48,243 - ERROR - Error fetching expenses: 1 validation error for Expense
date
  Input should be a valid string [type=string_type, input_value=datetime.datetime(2024, 1... 16, 22, 55, 31, 159000), input_type=datetime]
    For further information visit https://errors.pydantic.dev/2.4/v/string_type
Traceback (most recent call last):
  File "/home/srihari/Documents/Projects/App Dev/backend/app/api/endpoints.py", line 216, in get_expenses
    Expense(
  File "/home/srihari/miniconda3/envs/appdev_py312/lib/python3.12/site-packages/pydantic/main.py", line 164, in __init__
    __pydantic_self__.__pydantic_validator__.validate_python(data, self_instance=__pydantic_self__)
pydantic_core._pydantic_core.ValidationError: 1 validation error for Expense
date
  Input should be a valid string [type=string_type, input_value=datetime.datetime(2024, 1... 16, 22, 55, 31, 159000), input_type=datetime]
    For further information visit https://errors.pydantic.dev/2.4/v/string_type
2024-12-16 22:55:52,755 - ERROR - Error fetching expenses: 1 validation error for Expense
date
  Input should be a valid string [type=string_type, input_value=datetime.datetime(2024, 1... 16, 22, 55, 31, 159000), input_type=datetime]
    For further information visit https://errors.pydantic.dev/2.4/v/string_type
Traceback (most recent call last):
  File "/home/srihari/Documents/Projects/App Dev/backend/app/api/endpoints.py", line 216, in get_expenses
    Expense(
  File "/home/srihari/miniconda3/envs/appdev_py312/lib/python3.12/site-packages/pydantic/main.py", line 164, in __init__
    __pydantic_self__.__pydantic_validator__.validate_python(data, self_instance=__pydantic_self__)
pydantic_core._pydantic_core.ValidationError: 1 validation error for Expense
date
  Input should be a valid string [type=string_type, input_value=datetime.datetime(2024, 1... 16, 22, 55, 31, 159000), input_type=datetime]
    For further information visit https://errors.pydantic.dev/2.4/v/string_type
2024-12-16 22:55:53,345 - ERROR - Error fetching expenses: 1 validation error for Expense
date
  Input should be a valid string [type=string_type, input_value=datetime.datetime(2024, 1... 16, 22, 55, 31, 159000), input_type=datetime]
    For further information visit https://errors.pydantic.dev/2.4/v/string_type
Traceback (most recent call last):
  File "/home/srihari/Documents/Projects/App Dev/backend/app/api/endpoints.py", line 216, in get_expenses
    Expense(
  File "/home/srihari/miniconda3/envs/appdev_py312/lib/python3.12/site-packages/pydantic/main.py", line 164, in __init__
    __pydantic_self__.__pydantic_validator__.validate_python(data, self_instance=__pydantic_self__)
pydantic_core._pydantic_core.ValidationError: 1 validation error for Expense
date
  Input should be a valid string [type=string_type, input_value=datetime.datetime(2024, 1... 16, 22, 55, 31, 159000), input_type=datetime]
    For further information visit https://errors.pydantic.dev/2.4/v/string_type
2024-12-16 22:55:53,724 - ERROR - Error fetching expenses: 1 validation error for Expense
date
  Input should be a valid string [type=string_type, input_value=datetime.datetime(2024, 1... 16, 22, 55, 31, 159000), input_type=datetime]
    For further information visit https://errors.pydantic.dev/2.4/v/string_type
Traceback (most recent call last):
  File "/home/srihari/Documents/Projects/App Dev/backend/app/api/endpoints.py", line 216, in get_expenses
    Expense(
  File "/home/srihari/miniconda3/envs/appdev_py312/lib/python3.12/site-packages/pydantic/main.py", line 164, in __init__
    __pydantic_self__.__pydantic_validator__.validate_python(data, self_instance=__pydantic_self__)
pydantic_core._pydantic_core.ValidationError: 1 validation error for Expense
date
  Input should be a valid string [type=string_type, input_value=datetime.datetime(2024, 1... 16, 22, 55, 31, 159000), input_type=datetime]
    For further information visit https://errors.pydantic.dev/2.4/v/string_type
2024-12-16 22:56:08,382 - ERROR - Error fetching expenses: 1 validation error for Expense
date
  Input should be a valid string [type=string_type, input_value=datetime.datetime(2024, 1... 16, 22, 55, 31, 159000), input_type=datetime]
    For further information visit https://errors.pydantic.dev/2.4/v/string_type
Traceback (most recent call last):
  File "/home/srihari/Documents/Projects/App Dev/backend/app/api/endpoints.py", line 216, in get_expenses
    Expense(
  File "/home/srihari/miniconda3/envs/appdev_py312/lib/python3.12/site-packages/pydantic/main.py", line 164, in __init__
    __pydantic_self__.__pydantic_validator__.validate_python(data, self_instance=__pydantic_self__)
pydantic_core._pydantic_core.ValidationError: 1 validation error for Expense
date
  Input should be a valid string [type=string_type, input_value=datetime.datetime(2024, 1... 16, 22, 55, 31, 159000), input_type=datetime]
    For further information visit https://errors.pydantic.dev/2.4/v/string_type
2024-12-16 22:56:40,382 - ERROR - Error fetching expenses: 1 validation error for Expense
date
  Input should be a valid string [type=string_type, input_value=datetime.datetime(2024, 1... 16, 22, 55, 31, 159000), input_type=datetime]
    For further information visit https://errors.pydantic.dev/2.4/v/string_type
Traceback (most recent call last):
  File "/home/srihari/Documents/Projects/App Dev/backend/app/api/endpoints.py", line 216, in get_expenses
    Expense(
  File "/home/srihari/miniconda3/envs/appdev_py312/lib/python3.12/site-packages/pydantic/main.py", line 164, in __init__
    __pydantic_self__.__pydantic_validator__.validate_python(data, self_instance=__pydantic_self__)
pydantic_core._pydantic_core.ValidationError: 1 validation error for Expense
date
  Input should be a valid string [type=string_type, input_value=datetime.datetime(2024, 1... 16, 22, 55, 31, 159000), input_type=datetime]
    For further information visit https://errors.pydantic.dev/2.4/v/string_type
2024-12-16 22:56:44,562 - ERROR - Error fetching expenses: 1 validation error for Expense
date
  Input should be a valid string [type=string_type, input_value=datetime.datetime(2024, 1... 16, 22, 55, 31, 159000), input_type=datetime]
    For further information visit https://errors.pydantic.dev/2.4/v/string_type
Traceback (most recent call last):
  File "/home/srihari/Documents/Projects/App Dev/backend/app/api/endpoints.py", line 216, in get_expenses
    Expense(
  File "/home/srihari/miniconda3/envs/appdev_py312/lib/python3.12/site-packages/pydantic/main.py", line 164, in __init__
    __pydantic_self__.__pydantic_validator__.validate_python(data, self_instance=__pydantic_self__)
pydantic_core._pydantic_core.ValidationError: 1 validation error for Expense
date
  Input should be a valid string [type=string_type, input_value=datetime.datetime(2024, 1... 16, 22, 55, 31, 159000), input_type=datetime]
    For further information visit https://errors.pydantic.dev/2.4/v/string_type
2024-12-16 22:56:52,182 - ERROR - Error fetching expenses: 1 validation error for Expense
date
  Input should be a valid string [type=string_type, input_value=datetime.datetime(2024, 1... 16, 22, 55, 31, 159000), input_type=datetime]
    For further information visit https://errors.pydantic.dev/2.4/v/string_type
Traceback (most recent call last):
  File "/home/srihari/Documents/Projects/App Dev/backend/app/api/endpoints.py", line 216, in get_expenses
    Expense(
  File "/home/srihari/miniconda3/envs/appdev_py312/lib/python3.12/site-packages/pydantic/main.py", line 164, in __init__
    __pydantic_self__.__pydantic_validator__.validate_python(data, self_instance=__pydantic_self__)
pydantic_core._pydantic_core.ValidationError: 1 validation error for Expense
date
  Input should be a valid string [type=string_type, input_value=datetime.datetime(2024, 1... 16, 22, 55, 31, 159000), input_type=datetime]
    For further information visit https://errors.pydantic.dev/2.4/v/string_type
2024-12-16 22:56:53,994 - ERROR - Error fetching expenses: 1 validation error for Expense
date
  Input should be a valid string [type=string_type, input_value=datetime.datetime(2024, 1... 16, 22, 55, 31, 159000), input_type=datetime]
    For further information visit https://errors.pydantic.dev/2.4/v/string_type
Traceback (most recent call last):
  File "/home/srihari/Documents/Projects/App Dev/backend/app/api/endpoints.py", line 216, in get_expenses
    Expense(
  File "/home/srihari/miniconda3/envs/appdev_py312/lib/python3.12/site-packages/pydantic/main.py", line 164, in __init__
    __pydantic_self__.__pydantic_validator__.validate_python(data, self_instance=__pydantic_self__)
pydantic_core._pydantic_core.ValidationError: 1 validation error for Expense
date
  Input should be a valid string [type=string_type, input_value=datetime.datetime(2024, 1... 16, 22, 55, 31, 159000), input_type=datetime]
    For further information visit https://errors.pydantic.dev/2.4/v/string_type
2024-12-16 22:56:55,112 - ERROR - Error fetching expenses: 1 validation error for Expense
date
  Input should be a valid string [type=string_type, input_value=datetime.datetime(2024, 1... 16, 22, 55, 31, 159000), input_type=datetime]
    For further information visit https://errors.pydantic.dev/2.4/v/string_type
Traceback (most recent call last):
  File "/home/srihari/Documents/Projects/App Dev/backend/app/api/endpoints.py", line 216, in get_expenses
    Expense(
  File "/home/srihari/miniconda3/envs/appdev_py312/lib/python3.12/site-packages/pydantic/main.py", line 164, in __init__
    __pydantic_self__.__pydantic_validator__.validate_python(data, self_instance=__pydantic_self__)
pydantic_core._pydantic_core.ValidationError: 1 validation error for Expense
date
  Input should be a valid string [type=string_type, input_value=datetime.datetime(2024, 1... 16, 22, 55, 31, 159000), input_type=datetime]
    For further information visit https://errors.pydantic.dev/2.4/v/string_type
2024-12-16 22:56:56,116 - ERROR - Error fetching expenses: 1 validation error for Expense
date
  Input should be a valid string [type=string_type, input_value=datetime.datetime(2024, 1... 16, 22, 55, 31, 159000), input_type=datetime]
    For further information visit https://errors.pydantic.dev/2.4/v/string_type
Traceback (most recent call last):
  File "/home/srihari/Documents/Projects/App Dev/backend/app/api/endpoints.py", line 216, in get_expenses
    Expense(
  File "/home/srihari/miniconda3/envs/appdev_py312/lib/python3.12/site-packages/pydantic/main.py", line 164, in __init__
    __pydantic_self__.__pydantic_validator__.validate_python(data, self_instance=__pydantic_self__)
pydantic_core._pydantic_core.ValidationError: 1 validation error for Expense
date
  Input should be a valid string [type=string_type, input_value=datetime.datetime(2024, 1... 16, 22, 55, 31, 159000), input_type=datetime]
    For further information visit https://errors.pydantic.dev/2.4/v/string_type
2024-12-16 22:56:59,114 - INFO - Starting up the application
2024-12-16 22:56:59,120 - INFO - Successfully connected to the database
2024-12-16 22:57:43,846 - ERROR - Error creating expense: fromisoformat: argument must be str
2024-12-16 22:57:55,359 - INFO - Starting up the application
2024-12-16 22:57:55,368 - INFO - Successfully connected to the database
2024-12-17 12:25:24,049 - INFO - Starting up the application
2024-12-17 12:25:24,054 - INFO - Successfully connected to the database
2024-12-17 12:27:11,958 - ERROR - Error creating expense: 'str' object cannot be interpreted as an integer
Traceback (most recent call last):
  File "/home/srihari/Documents/Projects/App Dev/backend/app/api/endpoints.py", line 190, in create_expense
    expense_date = datetime.fromisoformat(expense.date.replace('Z', '+00:00'))
                                          ^^^^^^^^^^^^^^^^^^^^^^^^^^^^^^^^^^^
TypeError: 'str' object cannot be interpreted as an integer
2024-12-17 12:27:40,513 - ERROR - Error creating expense: 'str' object cannot be interpreted as an integer
Traceback (most recent call last):
  File "/home/srihari/Documents/Projects/App Dev/backend/app/api/endpoints.py", line 190, in create_expense
    expense_date = datetime.fromisoformat(expense.date.replace('Z', '+00:00'))
                                          ^^^^^^^^^^^^^^^^^^^^^^^^^^^^^^^^^^^
TypeError: 'str' object cannot be interpreted as an integer
2024-12-17 12:27:44,455 - ERROR - Error creating expense: 'str' object cannot be interpreted as an integer
Traceback (most recent call last):
  File "/home/srihari/Documents/Projects/App Dev/backend/app/api/endpoints.py", line 190, in create_expense
    expense_date = datetime.fromisoformat(expense.date.replace('Z', '+00:00'))
                                          ^^^^^^^^^^^^^^^^^^^^^^^^^^^^^^^^^^^
TypeError: 'str' object cannot be interpreted as an integer
2024-12-17 12:27:49,399 - ERROR - Error creating expense: 'str' object cannot be interpreted as an integer
Traceback (most recent call last):
  File "/home/srihari/Documents/Projects/App Dev/backend/app/api/endpoints.py", line 190, in create_expense
    expense_date = datetime.fromisoformat(expense.date.replace('Z', '+00:00'))
                                          ^^^^^^^^^^^^^^^^^^^^^^^^^^^^^^^^^^^
TypeError: 'str' object cannot be interpreted as an integer
2024-12-17 12:28:04,471 - INFO - Starting up the application
2024-12-17 12:28:04,474 - INFO - Successfully connected to the database
2024-12-17 12:28:46,029 - ERROR - Error creating expense: 'str' object cannot be interpreted as an integer
Traceback (most recent call last):
  File "/home/srihari/Documents/Projects/App Dev/backend/app/api/endpoints.py", line 190, in create_expense
    expense_date = datetime.fromisoformat(expense.date.replace('Z', '+00:00'))
                                          ^^^^^^^^^^^^^^^^^^^^^^^^^^^^^^^^^^^
TypeError: 'str' object cannot be interpreted as an integer
2024-12-17 12:28:51,341 - ERROR - Error creating expense: 'str' object cannot be interpreted as an integer
Traceback (most recent call last):
  File "/home/srihari/Documents/Projects/App Dev/backend/app/api/endpoints.py", line 190, in create_expense
    expense_date = datetime.fromisoformat(expense.date.replace('Z', '+00:00'))
                                          ^^^^^^^^^^^^^^^^^^^^^^^^^^^^^^^^^^^
TypeError: 'str' object cannot be interpreted as an integer
2024-12-17 12:29:20,004 - ERROR - Error creating expense: 'str' object cannot be interpreted as an integer
Traceback (most recent call last):
  File "/home/srihari/Documents/Projects/App Dev/backend/app/api/endpoints.py", line 190, in create_expense
    expense_date = datetime.fromisoformat(expense.date.replace('Z', '+00:00'))
                                          ^^^^^^^^^^^^^^^^^^^^^^^^^^^^^^^^^^^
TypeError: 'str' object cannot be interpreted as an integer
2024-12-17 12:29:23,571 - ERROR - Error creating expense: 'str' object cannot be interpreted as an integer
Traceback (most recent call last):
  File "/home/srihari/Documents/Projects/App Dev/backend/app/api/endpoints.py", line 190, in create_expense
    expense_date = datetime.fromisoformat(expense.date.replace('Z', '+00:00'))
                                          ^^^^^^^^^^^^^^^^^^^^^^^^^^^^^^^^^^^
TypeError: 'str' object cannot be interpreted as an integer
